Workbook

Sheet GeoDistributor
A1: f_crop | B1: parameter | C1: val_is | D1: y_0
B2: wooded_factor | C2: new | D2: 10 | F2: Wooded % of total
F3: =(Regions!J109*D2)/(Regions!J109*D2+SUM(Regions!G109:I109)) -> 0.23960361

Sheet Regions
A1: f_crop | B1: f_region | C1: parameter | D1: val_is | E1: y_0 | G1: Baseline semi-natural grasslands | M1: Potential pasture area from polygons | O1: Potential pasture area from raster
G2: Semi-natural meadows | H2: Semi-natural pastures | I2: Semi-natural pastures, thin soils | J2: Semi-natural pastures, wooded | K2: total | M2: area | O2: area | P2: factor
A3: Semi-natural pastures | B3: 1011 | C3: x0_crops | D3: rel | E3: =(M3-G3)/SUM(H3:I3) -> 1.6081167 | G3: 27.278 | H3: 7494.7202 | I3: 118.82348 | J3: 72.636451 | K3: =SUM(G3:J3) -> 7713.4582 | M3: 12270.745 | O3: =SUM(G3:J3)*MIN(P3,$S$3) -> 23913.326 | P3: 3.1002081 | Q3: =IF(P3>10,"cut-off","") | R3: Cut-off | S3: 10
A4: Semi-natural pastures | B4: 111 | C4: x0_crops | D4: rel | E4: =(M4-G4)/SUM(H4:I4) -> 4.0698518 | G4: 69.568 | H4: 4849.9222 | I4: 49.488179 | J4: 146.0004 | K4: =SUM(G4:J4) -> 5114.9788 | M4: 20009.442 | O4: =SUM(G4:J4)*MIN(P4,$S$3) -> 38702.969 | P4: 7.5665941 | Q4: =IF(P4>10,"cut-off","")
A5: Semi-natural pastures | B5: 1111 | C5: x0_crops | D5: rel | E5: =(M5-G5)/SUM(H5:I5) -> 1.5272826 | G5: 555.842 | H5: 8181.6908 | I5: 0 | J5: 51.643579 | K5: =SUM(G5:J5) -> 8789.1764 | M5: 13051.596 | O5: =SUM(G5:J5)*MIN(P5,$S$3) -> 16291.356 | P5: 1.8535703 | Q5: =IF(P5>10,"cut-off","")
A6: Semi-natural pastures | B6: 1112 | C6: x0_crops | D6: rel | E6: =(M6-G6)/SUM(H6:I6) -> 1.3902319 | G6: 66.54 | H6: 6156.632 | I6: 0.21036037 | J6: 30.445168 | K6: =SUM(G6:J6) -> 6253.8275 | M6: 8625.9784 | O6: =SUM(G6:J6)*MIN(P6,$S$3) -> 14909.977 | P6: 2.3841363 | Q6: =IF(P6>10,"cut-off","")
A7: Semi-natural pastures | B7: 112 | C7: x0_crops | D7: rel | E7: =(M7-G7)/SUM(H7:I7) -> 3.5733057 | G7: 29.89 | H7: 4504.0586 | I7: 27.708299 | J7: 280.01774 | K7: =SUM(G7:J7) -> 4841.6746 | M7: 16223.279 | O7: =SUM(G7:J7)*MIN(P7,$S$3) -> 17523.139 | P7: 3.6192311 | Q7: =IF(P7>10,"cut-off","")
A8: Semi-natural pastures | B8: 1121 | C8: x0_crops | D8: rel | E8: =(M8-G8)/SUM(H8:I8) -> 1.4282433 | G8: 204.764 | H8: 3246.2783 | I8: 3.6155521 | J8: 19.435349 | K8: =SUM(G8:J8) -> 3474.0932 | M8: 4846.4033 | O8: =SUM(G8:J8)*MIN(P8,$S$3) -> 8301.314 | P8: 2.3894908 | Q8: =IF(P8>10,"cut-off","")
A9: Semi-natural pastures | B9: 1122 | C9: x0_crops | D9: rel | E9: =(M9-G9)/SUM(H9:I9) -> 1.5416884 | G9: 37.422 | H9: 6416.1104 | I9: 21.375972 | J9: 3.7984626 | K9: =SUM(G9:J9) -> 6478.7069 | M9: 9962.0201 | O9: =SUM(G9:J9)*MIN(P9,$S$3) -> 11548.091 | P9: 1.7824685 | Q9: =IF(P9>10,"cut-off","")
A10: Semi-natural pastures | B10: 1123 | C10: x0_crops | D10: rel | E10: =(M10-G10)/SUM(H10:I10) -> 3.6232971 | G10: 112.206 | H10: 824.74702 | I10: 0.38252914 | J10: 0.42441473 | K10: =SUM(G10:J10) -> 937.75996 | M10: 3101.8955 | O10: =SUM(G10:J10)*MIN(P10,$S$3) -> 3378.1262 | P10: 3.6023357 | Q10: =IF(P10>10,"cut-off","")
A11: Semi-natural pastures | B11: 1124 | C11: x0_crops | D11: rel | E11: =(M11-G11)/SUM(H11:I11) -> 1.8357651 | G11: 146.396 | H11: 4898.9866 | I11: 0.90005356 | J11: 66.117379 | K11: =SUM(G11:J11) -> 5112.4 | M11: 9141.4371 | O11: =SUM(G11:J11)*MIN(P11,$S$3) -> 11964.503 | P11: 2.3402909 | Q11: =IF(P11>10,"cut-off","")
A12: Semi-natural pastures | B12: 1131 | C12: x0_crops | D12: rel | E12: =(M12-G12)/SUM(H12:I12) -> 1.9933837 | G12: 134.378 | H12: 6147.2112 | I12: 0 | J12: 59.470796 | K12: =SUM(G12:J12) -> 6341.06 | M12: 12388.129 | O12: =SUM(G12:J12)*MIN(P12,$S$3) -> 20576.927 | P12: 3.2450296 | Q12: =IF(P12>10,"cut-off","")
A13: Semi-natural pastures | B13: 1211 | C13: x0_crops | D13: rel | E13: =(M13-G13)/SUM(H13:I13) -> 2.0982383 | G13: 43.558 | H13: 1725.4056 | I13: 0 | J13: 5.2791696 | K13: =SUM(G13:J13) -> 1774.2428 | M13: 3663.8701 | O13: =SUM(G13:J13)*MIN(P13,$S$3) -> 7611.9169 | P13: 4.2902342 | Q13: =IF(P13>10,"cut-off","")
A14: Semi-natural pastures | B14: 1212 | C14: x0_crops | D14: rel | E14: =(M14-G14)/SUM(H14:I14) -> 2.3798524 | G14: 41.094 | H14: 1506.2651 | I14: 0 | J14: 0.39193354 | K14: =SUM(G14:J14) -> 1547.751 | M14: 3625.7827 | O14: =SUM(G14:J14)*MIN(P14,$S$3) -> 4322.487 | P14: 2.7927534 | Q14: =IF(P14>10,"cut-off","")
A15: Semi-natural pastures | B15: 1213 | C15: x0_crops | D15: rel | E15: =(M15-G15)/SUM(H15:I15) -> 1.7857401 | G15: 540.402 | H15: 6611.1608 | I15: 0 | J15: 19.636792 | K15: =SUM(G15:J15) -> 7171.1996 | M15: 12346.217 | O15: =SUM(G15:J15)*MIN(P15,$S$3) -> 13858.239 | P15: 1.9324854 | Q15: =IF(P15>10,"cut-off","")
... A108: Semi-natural pastures | B108: 913 | C108: x0_crops | D108: rel | E108: =(M108-G108)/SUM(H108:I108) -> 2.4592072 | G108: 59.886 | H108: 2699.2987 | I108: 10797.195 | J108: 1153.3107 | K108: =SUM(G108:J108) -> 14709.69 | M108: 33250.561 | O108: =SUM(G108:J108)*MIN(P108,$S$3) -> 23688.463 | P108: 1.6103985 | Q108: =IF(P108>10,"cut-off","")
A109: Semi-natural pastures, thin soils | B109: 1011 | C109: x0_crops | D109: rel | E109: =E3 -> 1.6081167 | F109: total | G109: =SUM(G3:G108) -> 11997.132 | H109: =SUM(H3:H108) -> 445155.13 | I109: =SUM(I3:I108) -> 73809.772 | J109: =SUM(J3:J108) -> 16730.803 | K109: =SUM(K3:K108) -> 547692.84 | M109: =SUM(M3:M108) -> 1206725.1 | O109: =SUM(O3:O108) -> 1838800.6
A110: Semi-natural pastures, thin soils | B110: 111 | C110: x0_crops | D110: rel | E110: =E4 -> 4.0698518
A111: Semi-natural pastures, thin soils | B111: 1111 | C111: x0_crops | D111: rel | E111: =E5 -> 1.5272826
A112: Semi-natural pastures, thin soils | B112: 1112 | C112: x0_crops | D112: rel | E112: =E6 -> 1.3902319
A113: Semi-natural pastures, thin soils | B113: 112 | C113: x0_crops | D113: rel | E113: =E7 -> 3.5733057
A114: Semi-natural pastures, thin soils | B114: 1121 | C114: x0_crops | D114: rel | E114: =E8 -> 1.4282433
A115: Semi-natural pastures, thin soils | B115: 1122 | C115: x0_crops | D115: rel | E115: =E9 -> 1.5416884
A116: Semi-natural pastures, thin soils | B116: 1123 | C116: x0_crops | D116: rel | E116: =E10 -> 3.6232971
A117: Semi-natural pastures, thin soils | B117: 1124 | C117: x0_crops | D117: rel | E117: =E11 -> 1.8357651
A118: Semi-natural pastures, thin soils | B118: 1131 | C118: x0_crops | D118: rel | E118: =E12 -> 1.9933837
A119: Semi-natural pastures, thin soils | B119: 1211 | C119: x0_crops | D119: rel | E119: =E13 -> 2.0982383
A120: Semi-natural pastures, thin soils | B120: 1212 | C120: x0_crops | D120: rel | E120: =E14 -> 2.3798524
A121: Semi-natural pastures, thin soils | B121: 1213 | C121: x0_crops | D121: rel | E121: =E15 -> 1.7857401
... A214: Semi-natural pastures, thin soils | B214: 913 | C214: x0_crops | D214: rel | E214: =E108 -> 2.4592072
A215: Semi-natural pastures, wooded | B215: 1011 | C215: x0_crops | D215: rel | E215: =E3*GeoDistributor!$D$2 -> 16.081167
A216: Semi-natural pastures, wooded | B216: 111 | C216: x0_crops | D216: rel | E216: =E4*GeoDistributor!$D$2 -> 40.698518
A217: Semi-natural pastures, wooded | B217: 1111 | C217: x0_crops | D217: rel | E217: =E5*GeoDistributor!$D$2 -> 15.272826
A218: Semi-natural pastures, wooded | B218: 1112 | C218: x0_crops | D218: rel | E218: =E6*GeoDistributor!$D$2 -> 13.902319
A219: Semi-natural pastures, wooded | B219: 112 | C219: x0_crops | D219: rel | E219: =E7*GeoDistributor!$D$2 -> 35.733057
A220: Semi-natural pastures, wooded | B220: 1121 | C220: x0_crops | D220: rel | E220: =E8*GeoDistributor!$D$2 -> 14.282433
A221: Semi-natural pastures, wooded | B221: 1122 | C221: x0_crops | D221: rel | E221: =E9*GeoDistributor!$D$2 -> 15.416884
A222: Semi-natural pastures, wooded | B222: 1123 | C222: x0_crops | D222: rel | E222: =E10*GeoDistributor!$D$2 -> 36.232971
A223: Semi-natural pastures, wooded | B223: 1124 | C223: x0_crops | D223: rel | E223: =E11*GeoDistributor!$D$2 -> 18.357651
A224: Semi-natural pastures, wooded | B224: 1131 | C224: x0_crops | D224: rel | E224: =E12*GeoDistributor!$D$2 -> 19.933837
...
